<?xml version="1.0" ?>

<robot name="KHR1HV">
    <!-- Constants (DONT WORK ANYMORE) -->
    <!-- <property name="M_PI"      value="3.14159265359" /> -->
    <!-- <property name="M_HALFPI"  value="1.57079632679" /> -->
    <!-- <property name="M_13PI_18" value="2.26892802759" /> -->
    <!-- Torso -->
    <link name="torso">
        <visual>
            <origin xyz="-0.0125 0 -0.0325" rpy="0 0 0" />
            <geometry>
                <box size="0.06 0.1 0.07" />
            </geometry>
            <material name="dark green">
                <color rgba="0 0.5 0 1"/>
            </material>
        </visual>
    </link>
      
    <joint name="world_joint" type="floating">
        <servo channel="-1" type="none" trim="0"/>
        <parent link="/world"/>
        <child link="torso"/>
        <origin xyz="0 0 0" rpy="0 0 0" />
    </joint>

    <!-- head -->
    <link name="neck_zy">
        <visual>
            <origin xyz="0 0 0" rpy="0 0 0" />
            <geometry>
                <box size="0.025 0.025 0.025" />
            </geometry>
            <material name="green">
                <color rgba="0 1 0 1"/>
            </material>
        </visual>    
    </link>

    <link name="head_y">
        <visual>
            <origin xyz="0 0 0" rpy="0 0 0" />
            <geometry>
                <box size="0.025 0.025 0.025" />
            </geometry>
            <material name="green">
                <color rgba="0 1 0 1"/>
            </material>
        </visual>    
    </link>

    <joint name="neck_yaw" type="revolute">
        <servo channel="13" type="RCSERVO_KONDO_KRS78X" trim="0"/>
        <parent link="torso"/>
        <child link="neck_zy"/>
        <origin xyz="0 0 0.03" rpy="0 0 0" />
        <axis xyz="0 0 1" />
	    <limit effort="100" velocity="100" lower="-1.57079632679" upper="1.57079632679"/>
    </joint>

    <joint name="neck_pitch" type="revolute">
        <servo channel="14" type="RCSERVO_KONDO_KRS78X" trim="0"/>
        <parent link="neck_zy"/>
        <child link="head_y"/>
        <origin xyz="0 0 0.03" rpy="0 0 0" />
        <axis xyz="0 1 0" />
	    <limit effort="100" velocity="100" lower="-1.57079632679" upper="1.57079632679"/>
    </joint>   
    
    <!-- Left Arm -->
    <link name="shoulder_left_yx">
        <visual>
            <origin xyz="0 0 0" rpy="0 0 0" />
            <geometry>
                <box size="0.025 0.025 0.025" />
            </geometry>
            <material name="green">
                <color rgba="0 1 0 1"/>
            </material>
        </visual>    
    </link>

    <link name="arm_left_upper_xz">
        <visual>
            <origin xyz="0 0 0" rpy="0 0 0" />
            <geometry>
                <box size="0.025 0.025 0.025" />
            </geometry>
            <material name="green">
                <color rgba="0 1 0 1"/>
            </material>
        </visual>    
    </link>

    <link name="arm_left_elbow_zx">
        <visual>
            <origin xyz="0 0 0" rpy="0 0 0" />
            <geometry>
                <box size="0.025 0.025 0.025" />
            </geometry>
            <material name="green">
                <color rgba="0 1 0 1"/>
            </material>
        </visual>    
    </link>

    <link name="arm_left_lower_x">
        <visual>
            <origin xyz="0 0 0" rpy="0 0 0" />
            <geometry>
                <box size="0.025 0.025 0.025" />
            </geometry>
            <material name="green">
                <color rgba="0 1 0 1"/>
            </material>
        </visual>    
    </link>

    <joint name="shoulder_left_pitch" type="revolute">
        <servo channel="1" type="RCSERVO_KONDO_KRS78X" trim="-357"/>
        <parent link="torso"/>
        <child link="shoulder_left_yx"/>
        <origin xyz="0 0.055 0.0" rpy="0 0 0" />
        <axis xyz="0 -1 0" />
        <limit effort="100" velocity="100" lower="-2.26892802759" upper="2.26892802759"/>
    </joint>

    <joint name="shoulder_left_roll" type="revolute">
        <servo channel="22" type="RCSERVO_KONDO_KRS78X" trim="-797"/>
        <parent link="shoulder_left_yx"/>
        <child link="arm_left_upper_xz"/>
        <origin xyz="0 0.025 0" rpy="0 0 0" />
        <axis xyz="1 0 0" />
        <limit effort="100" velocity="100" lower="-1.57079632679" upper="1.57079632679"/>
    </joint>

    <joint name="shoulder_left_yaw" type="revolute">
        <servo channel="23" type="RCSERVO_KONDO_KRS78X" trim="0"/>
        <parent link="arm_left_upper_xz"/>
        <child link="arm_left_elbow_zx"/>
        <origin xyz="0 0 -0.085" rpy="0 0 0" />
        <axis xyz="0 0 1" />
        <limit effort="100" velocity="100" lower="-1.57079632679" upper="1.57079632679"/>
    </joint>

    <joint name="elbow_left_roll" type="revolute">
        <servo channel="24" type="RCSERVO_KONDO_KRS78X" trim="-34"/>
        <parent link="arm_left_elbow_zx"/>
        <child link="arm_left_lower_x"/>
        <origin xyz="0 0 -0.030" rpy="0 0 0" />
        <axis xyz="1 0 0" />
        <limit effort="100" velocity="100" lower="-1.57079632679" upper="1.57079632679"/>
    </joint>    
   
    <!-- Right Arm -->
    <link name="shoulder_right_yx">
        <visual>
            <origin xyz="0 0 0" rpy="0 0 0" />
            <geometry>
                <box size="0.025 0.025 0.025" />
            </geometry>
            <material name="green">
                <color rgba="0 1 0 1"/>
            </material>
        </visual>    
    </link>

    <link name="arm_right_upper_xz">
        <visual>
            <origin xyz="0 0 0" rpy="0 0 0" />
            <geometry>
                <box size="0.025 0.025 0.025" />
            </geometry>
            <material name="green">
                <color rgba="0 1 0 1"/>
            </material>
        </visual>    
    </link>

    <link name="arm_right_elbow_zx">
        <visual>
            <origin xyz="0 0 0" rpy="0 0 0" />
            <geometry>
                <box size="0.025 0.025 0.025" />
            </geometry>
            <material name="green">
                <color rgba="0 1 0 1"/>
            </material>
        </visual>    
    </link>

    <link name="arm_right_lower_x">
        <visual>
            <origin xyz="0 0 0" rpy="0 0 0" />
            <geometry>
                <box size="0.025 0.025 0.025" />
            </geometry>
            <material name="green">
                <color rgba="0 1 0 1"/>
            </material>
        </visual>    
    </link>

    <joint name="shoulder_right_pitch" type="revolute">
        <servo channel="4" type="RCSERVO_KONDO_KRS78X" trim="363"/>
        <parent link="torso"/>
        <child link="shoulder_right_yx"/>
        <origin xyz="0 -0.055 0.0" rpy="0 0 0" />
        <axis xyz="0 1 0" />
        <limit effort="100" velocity="100" lower="-2.26892802759" upper="2.26892802759"/>
    </joint>

    <joint name="shoulder_right_roll" type="revolute">
        <servo channel="10" type="RCSERVO_KONDO_KRS78X" trim="791"/>
        <parent link="shoulder_right_yx"/>
        <child link="arm_right_upper_xz"/>
        <origin xyz="0 -0.025 0" rpy="0 0 0" />
        <axis xyz="1 0 0" />
        <limit effort="100" velocity="100" lower="-1.57079632679" upper="1.57079632679"/>
    </joint>

    <joint name="shoulder_right_yaw" type="revolute">
        <servo channel="11" type="RCSERVO_KONDO_KRS78X" trim="0"/>
        <parent link="arm_right_upper_xz"/>
        <child link="arm_right_elbow_zx"/>
        <origin xyz="0 0 -0.085" rpy="0 0 0" />
        <axis xyz="0 0 1" />
        <limit effort="100" velocity="100" lower="-1.57079632679" upper="1.57079632679"/>
    </joint>

    <joint name="elbow_right_roll" type="revolute">
        <servo channel="12" type="RCSERVO_KONDO_KRS78X" trim="-31"/>
        <parent link="arm_right_elbow_zx"/>
        <child link="arm_right_lower_x"/>
        <origin xyz="0 0 -0.03" rpy="0 0 0" />
        <axis xyz="1 0 0" />
        <limit effort="100" velocity="100" lower="-1.57079632679" upper="1.57079632679"/>
    </joint>       
    
    <!-- Left Leg -->
    <link name="hip_left_upper_zx">
        <visual>
            <origin xyz="0 0 0" rpy="0 0 0" />
            <geometry>
                <box size="0.025 0.025 0.025" />
            </geometry>
            <material name="green">
                <color rgba="0 1 0 1"/>
            </material>
        </visual>    
    </link>

    <link name="hip_left_lower_xy">
        <visual>
            <origin xyz="0 0 0" rpy="0 0 0" />
            <geometry>
                <box size="0.025 0.025 0.025" />
            </geometry>
            <material name="green">
                <color rgba="0 1 0 1"/>
            </material>
        </visual>    
    </link>

    <link name="leg_left_upper_yy">
        <visual>
            <origin xyz="0 0 0" rpy="0 0 0" />
            <geometry>
                <box size="0.025 0.025 0.025" />
            </geometry>
            <material name="green">
                <color rgba="0 1 0 1"/>
            </material>
        </visual>    
    </link>

    <link name="leg_left_lower_yy">
        <visual>
            <origin xyz="0 0 0" rpy="0 0 0" />
            <geometry>
                <box size="0.025 0.025 0.025" />
            </geometry>
            <material name="green">
                <color rgba="0 1 0 1"/>
            </material>
        </visual>    
    </link>

    <link name="ankle_left_yx">
        <visual>
            <origin xyz="0 0 0" rpy="0 0 0" />
            <geometry>
                <box size="0.025 0.025 0.025" />
            </geometry>
            <material name="green">
                <color rgba="0 1 0 1"/>
            </material>
        </visual>    
    </link>

    <link name="foot_left_x">
        <visual>
            <origin xyz="0 0 0" rpy="0 0 0" />
            <geometry>
                <box size="0.025 0.025 0.025" />
            </geometry>
            <material name="green">
                <color rgba="0 1 0 1"/>
            </material>
        </visual>    
    </link>
   
    <joint name="hip_left_yaw" type="revolute">
        <servo channel="2" type="RCSERVO_KONDO_KRS78X" trim=""/>
        <parent link="torso"/>
        <child link="hip_left_upper_zx"/>
        <origin xyz="-0.025 0.02 -0.065" rpy="0 0 0" />
        <axis xyz="0 0 1" />
	    <limit effort="100" velocity="100" lower="-1.57079632679" upper="1.57079632679"/>
    </joint>

    <joint name="hip_left_roll" type="revolute">
        <servo channel="21" type="RCSERVO_KONDO_KRS78X" trim="62"/>
        <parent link="hip_left_upper_zx"/>
        <child link="hip_left_lower_xy"/>
        <origin xyz="0 0.015 -0.025" rpy="0 0 0" />
        <axis xyz="1 0 0" />
        <limit effort="100" velocity="100" lower="-1.57079632679" upper="1.57079632679"/>
    </joint>

    <joint name="hip_left_pitch" type="revolute">
        <servo channel="18" type="RCSERVO_KONDO_KRS78X" trim="-6"/>
        <parent link="hip_left_lower_xy"/>
        <child link="leg_left_upper_yy"/>
        <origin xyz="0.01 0 -0.04" rpy="0 0 0" />
        <axis xyz="0 -1 0" />
        <limit effort="100" velocity="100" lower="-1.57079632679" upper="1.57079632679"/>
    </joint>

    <joint name="knee_left_pitch" type="revolute">
        <servo channel="17" type="RCSERVO_KONDO_KRS78X" trim="345"/>
        <parent link="leg_left_upper_yy"/>
        <child link="leg_left_lower_yy"/>
        <origin xyz="0 0 -0.06" rpy="0 0 0" />
        <axis xyz="0 -1 0" />
        <limit effort="100" velocity="100" lower="-1.57079632679" upper="1.57079632679"/>
    </joint>

    <joint name="ankle_left_pitch" type="revolute">
        <servo channel="19" type="RCSERVO_KONDO_KRS78X" trim="-188"/>
        <parent link="leg_left_lower_yy"/>
        <child link="ankle_left_yx"/>
        <origin xyz="0.02 0 -0.055" rpy="0 0 0" />
        <axis xyz="0 -1 0" />
        <limit effort="100" velocity="100" lower="-1.57079632679" upper="1.57079632679"/>
    </joint>

    <joint name="ankle_left_roll" type="revolute">
        <servo channel="20" type="RCSERVO_KONDO_KRS78X" trim="0"/>
        <parent link="ankle_left_yx"/>
        <child link="foot_left_x"/>
        <origin xyz="0 -0.015 -0.045" rpy="0 0 0" />
        <axis xyz="1 0 0" />
        <limit effort="100" velocity="100" lower="-1.57079632679" upper="1.57079632679"/>
    </joint>
    
   <!-- Right Leg -->
    <link name="hip_right_upper_zx">
        <visual>
            <origin xyz="0 0 0" rpy="0 0 0" />
            <geometry>
                <box size="0.025 0.025 0.025" />
            </geometry>
            <material name="green">
                <color rgba="0 1 0 1"/>
            </material>
        </visual>    
    </link>

    <link name="hip_right_lower_xy">
        <visual>
            <origin xyz="0 0 0" rpy="0 0 0" />
            <geometry>
                <box size="0.025 0.025 0.025" />
            </geometry>
            <material name="green">
                <color rgba="0 1 0 1"/>
            </material>
        </visual>    
    </link>

    <link name="leg_right_upper_yy">
        <visual>
            <origin xyz="0 0 0" rpy="0 0 0" />
            <geometry>
                <box size="0.025 0.025 0.025" />
            </geometry>
            <material name="green">
                <color rgba="0 1 0 1"/>
            </material>
        </visual>    
    </link>

    <link name="leg_right_lower_yy">
        <visual>
            <origin xyz="0 0 0" rpy="0 0 0" />
            <geometry>
                <box size="0.025 0.025 0.025" />
            </geometry>
            <material name="green">
                <color rgba="0 1 0 1"/>
            </material>
        </visual>    
    </link>

    <link name="ankle_right_yx">
        <visual>
            <origin xyz="0 0 0" rpy="0 0 0" />
            <geometry>
                <box size="0.025 0.025 0.025" />
            </geometry>
            <material name="green">
                <color rgba="0 1 0 1"/>
            </material>
        </visual>    
    </link>

    <link name="foot_right_x">
        <visual>
            <origin xyz="0 0 0" rpy="0 0 0" />
            <geometry>
                <box size="0.025 0.025 0.025" />
            </geometry>
            <material name="green">
                <color rgba="0 1 0 1"/>
            </material>
        </visual>    
    </link>
   
    <joint name="hip_right_yaw" type="revolute">
        <servo channel="3" type="RCSERVO_KONDO_KRS78X" trim="28"/>
        <parent link="torso"/>
        <child link="hip_right_upper_zx"/>
        <origin xyz="-0.025 -0.02 -0.065" rpy="0 0 0" />
        <axis xyz="0 0 1" />
	    <limit effort="100" velocity="100" lower="-1.57079632679" upper="1.57079632679"/>
    </joint>

    <joint name="hip_right_roll" type="revolute">
        <servo channel="9" type="RCSERVO_KONDO_KRS78X" trim="-9"/>
        <parent link="hip_right_upper_zx"/>
        <child link="hip_right_lower_xy"/>
        <origin xyz="0 -0.015 -0.025" rpy="0 0 0" />
        <axis xyz="1 0 0" />
        <limit effort="100" velocity="100" lower="-1.57079632679" upper="1.57079632679"/>
    </joint>

    <joint name="hip_right_pitch" type="revolute">
        <servo channel="6" type="RCSERVO_KONDO_KRS78X" trim="-12"/>
        <parent link="hip_right_lower_xy"/>
        <child link="leg_right_upper_yy"/>
        <origin xyz="0.01 0 -0.04" rpy="0 0 0" />
        <axis xyz="0 1 0" />
        <limit effort="100" velocity="100" lower="-1.57079632679" upper="1.57079632679"/>
    </joint>

    <joint name="knee_right_pitch" type="revolute">
        <servo channel="5" type="RCSERVO_KONDO_KRS78X" trim="-351"/>
        <parent link="leg_right_upper_yy"/>
        <child link="leg_right_lower_yy"/>
        <origin xyz="0 0 -0.06" rpy="0 0 0" />
        <axis xyz="0 1 0" />
        <limit effort="100" velocity="100" lower="-1.57079632679" upper="1.57079632679"/>
    </joint>

    <joint name="ankle_right_pitch" type="revolute">
        <servo channel="7" type="RCSERVO_KONDO_KRS78X" trim="175"/>
        <parent link="leg_right_lower_yy"/>
        <child link="ankle_right_yx"/>
        <origin xyz="0.02 0 -0.055" rpy="0 0 0" />
        <axis xyz="0 1 0" />
        <limit effort="100" velocity="100" lower="-1.57079632679" upper="1.57079632679"/>
    </joint>

    <joint name="ankle_right_roll" type="revolute">
        <servo channel="8" type="RCSERVO_KONDO_KRS78X" trim="-43"/>
        <parent link="ankle_right_yx"/>
        <child link="foot_right_x"/>
        <origin xyz="0 0.015 -0.045" rpy="0 0 0" />
        <axis xyz="-1 0 0" />
        <limit effort="100" velocity="100" lower="-1.57079632679" upper="1.57079632679"/>
    </joint>    

</robot>

